Workbook

Sheet Insurance
A1: age | B1: sex | C1: bmi | D1: children | E1: smoker | F1: region | G1: charges | H1: age group
A2: 19 | B2: female | C2: 27.9 | D2: 0 | E2: yes | F2: southwest | G2: 16884.924 | H2: =IF(A2<30,"18-29",IF(A2<40,"30-39",IF(A2<50,"40-49",IF(A2<60,"50-59","60+")))) -> 18-29
A3: 18 | B3: male | C3: 33.77 | D3: 1 | E3: no | F3: southeast | G3: 1725.5523 | H3: =IF(A3<30,"18-29",IF(A3<40,"30-39",IF(A3<50,"40-49",IF(A3<60,"50-59","60+")))) -> 18-29
A4: 28 | B4: male | C4: 33 | D4: 3 | E4: no | F4: southeast | G4: 4449.462 | H4: =IF(A4<30,"18-29",IF(A4<40,"30-39",IF(A4<50,"40-49",IF(A4<60,"50-59","60+")))) -> 18-29
A5: 33 | B5: male | C5: 22.705 | D5: 0 | E5: no | F5: northwest | G5: 21984.471 | H5: =IF(A5<30,"18-29",IF(A5<40,"30-39",IF(A5<50,"40-49",IF(A5<60,"50-59","60+")))) -> 30-39
A6: 32 | B6: male | C6: 28.88 | D6: 0 | E6: no | F6: northwest | G6: 3866.8552 | H6: =IF(A6<30,"18-29",IF(A6<40,"30-39",IF(A6<50,"40-49",IF(A6<60,"50-59","60+")))) -> 30-39
A7: 31 | B7: female | C7: 25.74 | D7: 0 | E7: no | F7: southeast | G7: 3756.6216 | H7: =IF(A7<30,"18-29",IF(A7<40,"30-39",IF(A7<50,"40-49",IF(A7<60,"50-59","60+")))) -> 30-39
A8: 46 | B8: female | C8: 33.44 | D8: 1 | E8: no | F8: southeast | G8: 8240.5896 | H8: =IF(A8<30,"18-29",IF(A8<40,"30-39",IF(A8<50,"40-49",IF(A8<60,"50-59","60+")))) -> 40-49
A9: 37 | B9: female | C9: 27.74 | D9: 3 | E9: no | F9: northwest | G9: 7281.5056 | H9: =IF(A9<30,"18-29",IF(A9<40,"30-39",IF(A9<50,"40-49",IF(A9<60,"50-59","60+")))) -> 30-39
A10: 37 | B10: male | C10: 29.83 | D10: 2 | E10: no | F10: northeast | G10: 6406.4107 | H10: =IF(A10<30,"18-29",IF(A10<40,"30-39",IF(A10<50,"40-49",IF(A10<60,"50-59","60+")))) -> 30-39
A11: 60 | B11: female | C11: 25.84 | D11: 0 | E11: no | F11: northwest | G11: 28923.137 | H11: =IF(A11<30,"18-29",IF(A11<40,"30-39",IF(A11<50,"40-49",IF(A11<60,"50-59","60+")))) -> 60+
A12: 25 | B12: male | C12: 26.22 | D12: 0 | E12: no | F12: northeast | G12: 2721.3208 | H12: =IF(A12<30,"18-29",IF(A12<40,"30-39",IF(A12<50,"40-49",IF(A12<60,"50-59","60+")))) -> 18-29
A13: 62 | B13: female | C13: 26.29 | D13: 0 | E13: yes | F13: southeast | G13: 27808.725 | H13: =IF(A13<30,"18-29",IF(A13<40,"30-39",IF(A13<50,"40-49",IF(A13<60,"50-59","60+")))) -> 60+
... A1339: 61 | B1339: female | C1339: 29.07 | D1339: 0 | E1339: yes | F1339: northwest | G1339: 29141.36 | H1339: =IF(A1339<30,"18-29",IF(A1339<40,"30-39",IF(A1339<50,"40-49",IF(A1339<60,"50-59","60+")))) -> 60+

Sheet Data Dictionary
A1: Column | B1: Meaning | C1: Data Type
A2: age | B2: age of the individual | C2: Numeric
A3: sex | B3: sex of the individual | C3: Categorical
A4: bmi | B4: body mass index | C4: Numeric
A5: children | B5: number of children/dependents | C5: Numeric
A6: smoker | B6: smoking status | C6: Categorical
A7: region | B7: geographic region | C7: Categorical
A8: charges | B8: medical insurance charges | C8: Numeric

Sheet Research Questions
A1: Healthcare Cost Analysis - Research Questions
A3: 1. How do medical insurance charges vary by age?
A4: 2. How does BMI relate to medical insurance charges?
A5: 3. Are insurance charges different between smokers and non-smokers?
A6: 4. How do insurance charges vary by number of children?
A7: 5. Does age, BMI, smoking status, or number of children have the strongest relationship with insurance charges?
A8: 6. Can age and BMI be used to predict insurance charges?

Sheet Analysis
A1: 1. How do medical insurance charges vary by age?
A3: Mean Charges | B3: =AVERAGE(Insurance!G:G) -> 13270.422 | H3: Insurance charges increased across every age group in this dataset. The average rose from $9,182.49 for ages 18–29 to $21,248.02 for ages 60+.
A4: Median Charges | B4: =MEDIAN(Insurance!G:G) -> 9382.033 | H4: *the age groups aren't equally represented
A5: Minimum Charges | B5: =MIN(Insurance!G:G) -> 1121.8739
A6: Maximum Charges | B6: =MAX(Insurance!G:G) -> 63770.428
A7: Standard Deviation | B7: =_xlfn.STDEV.S(Insurance!G:G) -> 12110.011
A10: Age Group | B10: Average Charges | C10: Number of Records
A11: 18-29 | B11: =AVERAGEIF(Insurance!H:H, A11, Insurance!G:G) -> 9182.4871 | C11: =COUNTIF(Insurance!H:H,A11) -> 417
A12: 30-39 | B12: =AVERAGEIF(Insurance!H:H, A12, Insurance!G:G) -> 11738.784 | C12: =COUNTIF(Insurance!H:H,A12) -> 257
A13: 40-49 | B13: =AVERAGEIF(Insurance!H:H, A13, Insurance!G:G) -> 14399.204 | C13: =COUNTIF(Insurance!H:H,A13) -> 279
A14: 50-59 | B14: =AVERAGEIF(Insurance!H:H, A14, Insurance!G:G) -> 16495.233 | C14: =COUNTIF(Insurance!H:H,A14) -> 271
A15: 60+ | B15: =AVERAGEIF(Insurance!H:H, A15, Insurance!G:G) -> 21248.022 | C15: =COUNTIF(Insurance!H:H,A15) -> 114
A18: 2. How does BMI relate to medical insurance charges?
A20: Correlation between BMI and Charges | B20: =CORREL(Insurance!C:C, Insurance!G:G) -> 0.19834097
B21: BMI has a weak positive relationship with insurance charges (r=0.1983)
A42: 3. Are insurance charges different between smokers and non-smokers?
A44: Smoking Status | B44: Average Charges | C44: Number of Records
A45: yes | B45: =AVERAGEIF(Insurance!E:E,A45,Insurance!G:G) -> 32050.232 | C45: =COUNTIF(Insurance!E:E,A45) -> 274
A46: no | B46: =AVERAGEIF(Insurance!E:E,A46,Insurance!G:G) -> 8434.2683 | C46: =COUNTIF(Insurance!E:E,A46) -> 1064
D50: Average insurance charges were substantially higher for smokers ($32,050) than for non-smokers ($8,434) in this dataset.
A64: 4. How do insurance charges vary by number of children?
A66: Number of Children | B66: Average Charges | C66: Number of Records
A67: 0 | B67: =AVERAGEIF(Insurance!D:D,A67,Insurance!G:G) -> 12365.976 | C67: =COUNTIF(Insurance!D:D,A67) -> 574
A68: 1 | B68: =AVERAGEIF(Insurance!D:D,A68,Insurance!G:G) -> 12731.172 | C68: =COUNTIF(Insurance!D:D,A68) -> 324
A69: 2 | B69: =AVERAGEIF(Insurance!D:D,A69,Insurance!G:G) -> 15073.564 | C69: =COUNTIF(Insurance!D:D,A69) -> 240
A70: 3 | B70: =AVERAGEIF(Insurance!D:D,A70,Insurance!G:G) -> 15355.318 | C70: =COUNTIF(Insurance!D:D,A70) -> 157
A71: 4 | B71: =AVERAGEIF(Insurance!D:D,A71,Insurance!G:G) -> 13850.656 | C71: =COUNTIF(Insurance!D:D,A71) -> 25
A72: 5 | B72: =AVERAGEIF(Insurance!D:D,A72,Insurance!G:G) -> 8786.0352 | C72: =COUNTIF(Insurance!D:D,A72) -> 18
D78: Average insurance charges varied by number of children. Charges were highest for individuals with 3 children ($15,355), followed by those with 2 children ($15,074). Individuals with 5 children had the lowest average charges ($8,786). The 4- and 5-child groups had relatively few records, so those averages should be interpreted cautiously
A90: 5. Does age, BMI, smoking status, or number of children have the strongest relationship with insurance charges?
A92: Variable | B92: Correlation with Charges
A93: Age | B93: =CORREL(Insurance!A:A, Insurance!G:G) -> 0.29900819 | C93: weak positive relationship
A94: BMI | B94: =CORREL(Insurance!C:C, Insurance!G:G) -> 0.19834097 | C94: weak positive relationship
A95: Children | B95: =CORREL(Insurance!D:D, Insurance!G:G) -> 0.067998227 | C95: weak positive relationship
A97: Smoking Status | B97: Group Difference in Average Charges
A98: Smoker vs Non-smoker | B98: =B45-B46 -> 23615.964
A100: Age had the strongest correlation with insurance charges among the numberical variables examines (r = 0.2990), followed by BMI (r = 0.1983) and number of children (r = 0.0680). Smoking status showed a much larger difference in average charges between groups, with smokers averaging about $23,616 more than non-smokers.
A102: 6. Can age and BMI be used to predict insurance charges?
A103: Dependent Variable | B103: Insurance Charges
A104: Predictor 1 | B104: Age
...

Sheet Regression
A1: SUMMARY OUTPUT
A3: Regression Statistics
A4: Multiple R | B4: 0.34289722
A5: R Square | B5: 0.1175785
A6: Adjusted R Square | B6: 0.11625553
A7: Standard Error | B7: 11388.221
A8: Observations | B8: 1337
A10: ANOVA
B11: df | C11: SS | D11: MS | E11: F | F11: Significance F
A12: Regression | B12: 2 | C12: 2.3052576e+10 | D12: 1.1526288e+10 | E12: 88.874603 | F12: 5.8337204e-37
A13: Residual | B13: 1334 | C13: 1.7300857e+11 | D13: 1.2969158e+08
A14: Total | B14: 1336 | C14: 1.9606115e+11
B16: Coefficients | C16: Standard Error | D16: t Stat | E16: P-value | F16: Lower 95% | G16: Upper 95% | H16: Lower 95.0% | I16: Upper 95.0%
A17: Intercept | B17: -6470.2146 | C17: 1745.1569 | D17: -3.7075259 | E17: 0.00021787409 | F17: -9893.7656 | G17: -3046.6637 | H17: -9893.7656 | I17: -3046.6637
A18: Age | B18: 242.63751 | C18: 22.317268 | D18: 10.872187 | E18: 1.9355515e-26 | F18: 198.85674 | G18: 286.41827 | H18: 198.85674 | I18: 286.41827
A19: BMI | B19: 333.31214 | C19: 51.382155 | D19: 6.4869242 | E19: 1.2313181e-10 | F19: 232.51352 | G19: 434.11077 | H19: 232.51352 | I19: 434.11077
A21: Age and BMI were statistically significant predictors of insurance charges in the regression model, but together they explained only 11.8% of the variation in charges. This suggests that age and BMI provide some predictive information, but they are not sufficient on their own to strongly predict individual insurance charges

Sheet Findings
A1: Project Title
A2: Healthcare Insurance Charges: Exploratory Data Analysis & Statistical Analysis
A4: Objective
A5: Analyze insurance charges and examine how charges vary across age, BMI, smoking status, and number of children.
A7: Key Findings
A8: 1. Age and Insurance Charges
A10: Average insurance charges increased across every age group, from $9,182 for individuals ages 18–29 to $21,248 for individuals age 60+. This shows a clear positive pattern between age group and average charges in this dataset.
A12: 2. BMI and Insurance Charges
A14: BMI had a weak positive relationship with insurance charges (r = 0.1983), indicating that BMI alone had a limited relationship with charges in this dataset.
A16: 3. Smoking Status and Insurance Charges
A18: Average insurance charges were substantially higher for smokers ($32,050) than for non-smokers ($8,434) in this dataset.
A20: 4. Number of Children and Insurance Charges
... A30: Age and BMI were statistically significant predictors of insurance charges, but together they explained only 11.8% of the variation in charges. This indicates that other factors likely contribute substantially to differences in insurance costs.
